Workbook
Name High: [2]Source!$P$42:$P$43
Name High: Source!$P$42:$P$43
Name Low: [2]Source!$L$42
Name Low: Source!$L$42
Name Low_To_Moderate: [3]Source!$M$42:$M$43
Name LowToModerate: Source!$M$42:$M$43
Name Moderate: [2]Source!$N$42
Name Moderate: Source!$N$42
Name Moderate_To_High: [3]Source!$O$42:$O$43
Name ModerateToHigh: Source!$O$42:$O$43

Sheet Halaman Judul
E1: LAMPIRAN
E2: KEPUTUSAN DEPUTI BIDANG KEUANGAN DAN MANAJEMEN RISIKO
E3: NOMOR : | F3: SK-6/DKU.MBU/10/2023
E4: TENTANG: | F4: PETUNJUK TEKNIS PROSES MANAJEMEN RISIKO DAN AGREGASI PADA TAKSONOMI RISIKO PORTOFOLIO BADAN USAHA MILIK NEGARA
E5: TANGGAL : | F5: 26 OKTOBER 2023
E9: FORMAT PENYUSUNAN PERENCANAAN
E10: MANAJEMEN RISIKO
E11: BADAN USAHA MILIK NEGARA
E28: KEMENTERIAN BUMN
E29: JALAN MEDAN MERDEKA SELATAN NO.13 JAKARTA 10110

Sheet Daftar Isi
A2: DAFTAR ISI
B4: 1 | C4: Format Metrik Strategi Risiko | L4: Lengkap
B5: 2 | C5: Format Pilihan Sasaran&Strategi Bisnis | L5: Belum Lengkap
B6: 3 | C6: Format Profil Risiko
B7: 4 | C7: Format Risiko Inheren Kuantitatif
B8: 5 | C8: Format Risiko Inheren Kualitatif
B9: 6 | C9: Format Risiko Residual Kuantitatif
B10: 7 | C10: Format Risiko Residual Kualitatif
B11: 8 | C11: Format Rencana Perlakuan Risiko
B12: 9 | C12: Format Heatmap
B13: 10 | C13: Kriteria Dampak dan Probabilitas
B14: 11 | C14: Definisi Taksonomi Risiko
B15: 12 | C15: Petunjuk Pengisian Data Perencanaan Keuangan pada SIM KBUMN Melalui Platform Anaplan
B16: 13 | C16: Ilustrasi Contoh Perhitungan Ambang Batas Risiko dan Pola Integrasi Risiko

Sheet Metrik Strategi Risiko
A1: Kembali ke Daftar Isi
A2: Penerimaan Risiko Level Entitas/Korporate
A3: Data Item | B3: Nilai Kapasitas Risiko Perusahaan | C3: Nilai Selera Risiko Perusahaan | D3: Nilai Toleransi Risiko Perusahaan | E3: Nilai Batasan Risiko
A4: Jenis Data | B4: Nilai rupiah/mata uang fungsional pembukuan | C4: Nilai rupiah/mata uang fungsional pembukuan | D4: Nilai rupiah/mata uang fungsional pembukuan | E4: Nilai rupiah/mata uang fungsional pembukuan
A5: Petunjuk | B5: Diisi dengan nilai kapasitas risiko yang dimiliki oleh perusahaan. Kapasitas risiko perusahaan adalah maksimum nilai Risiko yang dapat ditanggung perusahaan berdasarkan modal, net working capital, likuiditas, total kemampuan pendanaan perusahaan, atau nilai batasan lainnya. | C5: Diisi dengan nilai selera risiko yang dihitung berdasarkan nilai batasan keseluruhan risiko yang bersedia diambil untuk mendapatkan hasil yang diharapkan. | D5: Diisi dengan nilai batasan risiko yang dapat ditoleransi dari nilai Selera Risiko yang bersedia diambil. Nilai ini lebih besar dari nilai Selera Risiko. | E5: Diisi dengan nilai batasan risiko yang akan didistribusikan dan menjadi acuan bagi unit pemilik risiko.
A6: Notes | B6: (satuan dalam rupiah/mata uang fungsional pembukuan). | C6: (satuan dalam rupiah/mata uang fungsional pembukuan). | D6: (satuan dalam rupiah/mata uang fungsional pembukuan). | E6: (satuan dalam rupiah/mata uang fungsional pembukuan).
A7: Start pengisian | B7: 5.02 | D7: =30.26%*B7 -> 1.519052 | E7: 0.36
A9: Metrik Strategi Risiko
A10: Data Item | B10: No. | C10: Nama BUMN | D10: Kode BUMN | E10: Kategori Risiko BUMN | F10: Kategori Risiko T2 & T3 KBUMN | G10: Risk Appetite Statement | H10: Sikap Terhadap Risiko | I10: Parameter | J10: Satuan Ukuran | K10: Nilai Batasan/Limit
A11: Jenis Data | B11: Number | C11: Dropdown list | D11: Formula | E11: Free Text | F11: Dropdown list | G11: Free Text | H11: Dropdown List | I11: Free Text | J11: Free Text/Ratio/Number | K11: Number
A12: Petunjuk | D12: Kolom ini tidak perlu diisi. Akan diisi oleh Kementerian BUMN | E12: Diisi dengan taksonomi risiko yang berlaku pada masing-masing BUMN | F12: Diisi dengan pilihan kategori risiko Portofolio BUMN Kementerian BUMN berikut: 1. Risiko Fiskal - Dividen 2. Risiko Fiskal - PMN 3. Risiko Fiskal - Subsidi & Kompensasi 4. Risiko Kebijakan - SDM 5. Risiko Kebijakan - Sektoral 6. Risiko Komposisi - Konsentrasi Portofolio 7. Risiko Struktur - Struktur Korporasi 8. Risiko Restrukturisasi & Reorganisasi - Penggabungan, Pengambilalihan, Peleburan, Pemisahan, Pembubaran, Likuidasi, Kemitraan, dan Restrukturisasi 9. Risiko Industri Umum - Formulasi Strategis 10. Risiko Industri Umum - Pasar & Makroekonomi 11. Risiko Industri Umum - Keuangan 12. Risiko Industri Umum - Reputasi & Kepatuhan 13. Risiko Industri Umum - Proyek 14. Risiko Industri Umum - Teknologi & Keamanan Siber 15. Risiko Industri Umum - Sosial & Lingkungan 16. Risiko Industri Umum - Operasional 17. Risiko Industri Perbankan - Kredit 18. Risiko Industri Perbankan - Likuiditas 19. Risiko Industri Asuransi - Investasi 20. Risiko Industri Asuransi - Aktuarial 21. Risiko lainnya | G12: Diisikan dengan pernyataan selera risiko BUMN | H12: Diisikan dengan postur selera risiko atas suatu taksonomi risiko yang terdiri dari: 1. Tidak Toleran 2. Konservatif 3. Moderat 4. Strategis | I12: Diisi dengan parameter risiko yang mencerminkan pernyataan selera risiko BUMN. Apabila terdapat lebih dari satu parameter, maka parameter berikutnya ditambahkan pada row dibawahnya dan tidak diinput pada satu cell row yang sama dengan parameter sebelumnya. | J12: Diisikan dengan satuan ukuran atau nominal atas level selera risiko relevan yang dipilih | K12: Diisi dengan nilai batasan atas parameter yang telah ditetapkan. Nilai batasan ini tidak boleh dilanggar dan akan menjadi barometer penentu suatu sasaran dan strategi diterima dan menjadi usulan dalam rancangan RKAP.
A13: Notes | F13: - BUMN pada Industri Umum tidak boleh memetakan dalam kategori Risiko Industri Perbankan dan Asuransi - BUMN pada Industri perbankan & asuransi ikut memetakan dalam kategori risiko Industri Umum | I13: Contoh parameter: - Tingkat fraud; - Tingkat fatality; - Tingkat kegagalan inovasi; - Rasio biaya operasi; - Dan lain-lain. | J13: Contoh: - % - kali - dan lain-lain
A14: Start pengisian | B14: 1 | C14: PT Perusahaan Listrik Negara (Persero) | D14: =IFERROR(VLOOKUP(C14,Master!$D$2:$E$50,2,0),"") -> PLNA | E14: T4 | F14: 16. Risiko Industri Umum - Operasional | G14: PT PLN Batam memiliki CAUTIOUS appetite terhadap gangguan operasional yang mempengaruhi kualitas (power quality), keandalan (reliability), dan ketersediaan (availability) pasokan listrik dan aset perusahaan, dengan tetap mempertahankan efisiensi. | H14: Moderat | I14: Pemehuan
B15: 2 | C15: PT Perusahaan Listrik Negara (Persero) | D15: =IFERROR(VLOOKUP(C15,Master!$D$2:$E$50,2,0),"") -> PLNA | E15: T4 | F15: 16. Risiko Industri Umum - Operasional | G15: PT PLN Batam memiliki CAUTIOUS appetite terhadap gangguan operasional yang mempengaruhi kualitas (power quality), keandalan (reliability), dan ketersediaan (availability) pasokan listrik dan aset perusahaan, dengan tetap mempertahankan efisiensi. | H15: Moderat | I15: Pemehuan
B16: 1 | C16: PT Perusahaan Listrik Negara (Persero) | D16: =IFERROR(VLOOKUP(C16,Master!$D$2:$E$50,2,0),"") -> PLNA | E16: T4 | F16: 16. Risiko Industri Umum - Operasional | G16: PT PLN Batam memiliki CAUTIOUS appetite terhadap gangguan operasional yang mempengaruhi kualitas (power quality), keandalan (reliability), dan ketersediaan (availability) pasokan listrik dan aset perusahaan, dengan tetap mempertahankan efisiensi. | H16: Moderat | I16: Pemehuan

Sheet Pilihan Sasaran&Strategi Bisnis
A1: Kembali ke Daftar Isi
A2: Data Item | B2: No | C2: Pilihan Sasaran | D2: Pilihan Strategi | E2: Hasil yang diharapkan dapat diterima perusahaan | F2: Nilai Risiko Yang Akan Timbul | G2: Nilai limit risiko sesuai dengan parameter risiko dalam Metrik Strategi Risiko | H2: Keputusan Penetapan
A3: Jenis Data | B3: Number | C3: Free Text | D3: Free Text | E3: Free Text | F3: Free Text | G3: Free Text | H3: Dropdown list
A4: Petunjuk | C4: Diisi dengan berbagai pilihan sasaran yang menjadi dinamika dalam perencanaan penyusunan rancangan RKAP. | D4: Diisi dengan berbagai pilihan strategi yang menjadi dinamika dalam perencanaan penyusunan rancangan RKAP. | E4: Diisi dengan nilai kuantitatif dalam mata uang rupiah/mata uang fungsional pembukuan atas hasil yang diharapkan dari pelaksanaan sasaran dan strategi yang akan dijalankan pada tahun 2024. | F4: Diisi dengan nilai risiko yang akan timbul sebagai konsekuensi dari suatu sasaran dan strategi yang akan dijalankan. | G4: Diisi dengan batasan risiko / limit risiko sesuai dengan parameter risiko dalam metrik strategi risiko. | H4: Diisi dengan pilihan: - Lanjut: apabila sasaran dan strategi diterima menjadi sasaran dan strategi yang akan dijalankan dalam rancangan RKAP. - Tidak Lanjut: apabila sasaran dan strategi tidak dapat diterima dan tidak dapat dimasukkan dalam sasaran dan strategi yang akan dijalankan di dalam rancangan RKAP.
A5: Notes | C5: Sasaran adalah: tujuan yang akan dicapai meliputi tingkat pertumbuhan dan kesehatan perusahaan serta sasaran bidang/unit kegiatan secara kuantitatif dan spesifik setiap tahunnya. | D5: Strategi adalah cara yang digunakan untuk mencapai sasaran, meliputi strategi korporasi sesuai posisi perusahaan, strategi bisnis, dan strategi fungsional tiap bidang/unit kegiatan. | E5: (satuan dalam rupiah/mata uang fungsional pembukuan). | F5: (satuan dalam rupiah/mata uang fungsional pembukuan). | H5: - Keputusan pemilihan sasaran tersebut terdiri dari: (i) lanjut, apabila imbal hasil (return) yang akan diperoleh sebanding dengan risiko (risk) yang dapat diterima oleh perusahaan, dan (ii) tidak lanjut, apabila risiko (risk) di luar ambang yang dapat diterima oleh perusahaan walaupun imbal hasil (return) tinggi. - Dokumentasi seluruh hasil pemilihan sasaran baik lanjut maupun tidak lanjut dimuat dalam dokumen perencanaan strategis BUMN baik RJP atau RKAP.
A6: Contoh pengisian | C6: Peningkatan segmen korporasi dengan pertumbuhan 5% yang akan dijalankan melalui strategi: | E6: Tambahan penjualan Rp800 miliar | F6: Penurunan cashflow operasi Rp200 miliar | G6: Penurunan cashflow operasi, limitnya sampai dengan Rp500 miliar | H6: Lanjut
D7: 1. Pemberian diskon harga sampai dengan 10% bagi korporasi yang membeli lebih dari 10 ribu ton per bulan. | H7: Tidak Lanjut
D8: 2. Pelanggan korporasi baru diberikan fleksibilitas pembayaran sampai dengan 6 bulan. | H8: Lanjut
A9: Start pengisian
A10: Start pengisian | C10: Meningkatkan keandalan suply dan kualitas layanan | G10: Pencapaian Biaya Pokok Penjualan (BPP) Non MPP (Rp/kWh) Rp 1.453,13
D11: Implementasi program anti blackout | E11: Penurunan kejadian gangguan | G11: EBITDA terealisasi sesuai target Rp 1.617,69 Miliar | H11: Lanjut
G12: ROIC terelasasi seusai target 5,65%
G13: Pengendalian penggunaan Anggaran Investasi sesuai RKAP 2024
G14: Compliance (GCG, Zero Fatality, Kepatuhan K3L, SPI, Reporting, Busdev Alignment)
G15: Optimalisasi Penempatan Dana
G16: Ketersediaan Saldo Kas Minimal
G17: Pemenuhan Roadmap Perbaikan Penerapan Manajemen Risiko
G18: Pengendalian atas Pengaruh Fluktuasi Selisih Kurs dengan Melaksanakan Transaksi Lindung Nilai (Hedging)
G19: Kecepatan Tagihan Vendor
G20: Ketersediaan Pendanaan Pembangunan Pembangkit PLTGU 120 MW di Tahun 2024
G21: Human Capital Readiness (HCR) & Organizational Capital Readiness (OCR) dan Produktifitas Pegawai
G22: Tingkat Optimalisasi Kredit Pajak dan Pajak Masukan
D28: Penguatan sistem jaringan

Sheet SUMMARY
AO1: Target Risiko Residual | BY1: RENCANA PERLAKUAN RISIKO | CB1: RENCANA PERLAKUAN RISIKO
BU2: Data Item | BV2: No. | BW2: BUMN | BX2: Kode BUMN | BY2: No. Risiko | BZ2: No. Penyebab Risiko | CA2: Penyebab risiko | CB2: Opsi Perlakuan Risiko | CC2: Jenis Rencana Perlakuan Risiko | CD2: Rencana Perlakuan Risiko | CE2: Output Perlakuan Risiko | CF2: Biaya Perlakuan Risiko (Rp/Mata Uang Lain) | CG2: Pos Anggaran | CH2: PRK | CI2: Jenis Program Dalam RKAP | CJ2: PIC | CK2: Timeline (Bulan)
A3: Kembali ke Daftar Isi | AI3: 610000000000 | AJ3: Risk Limit PLN Batam Tahun 2026 | AL3: No. | AM3: No. Risiko | AN3: Peristiwa risiko | AO3: Nilai Dampak | AS3: Skala Dampak | AW3: Nilai Probabilitas | BA3: Skala Probabilitas | BE3: Eksposur Risiko | BI3: Skala Risiko | BM3: Level Risiko | CK3: 1 | CL3: =CK3+1 -> 2 | CM3: =CL3+1 -> 3 | CN3: =CM3+1 -> 4 | CO3: =CN3+1 -> 5 | CP3: =CO3+1 -> 6 | CQ3: =CP3+1 -> 7 | CR3: =CQ3+1 -> 8 | CS3: =CR3+1 -> 9 | ... CV3: =CU3+1 -> 12
A4: Data Item | B4: No. | C4: Nama BUMN | D4: AP/SH | E4: Bidang/Unit (Drop Down) | F4: Sasaran BUMN | G4: No KM/KPI Bidang/Unit | H4: Sasaran PLN BATAM (KM UNIT/BIDANG) (Dropdown) | I4: Sasaran KBUMN | J4: Taksonomi Risiko PLN (T3) | K4: Kategori Risiko T2 & T3 KBUMN | L4: No. Risiko | M4: Peristiwa Risiko | N4: Deskripsi Peristiwa risiko | O4: No. Penyebab Risiko (Huruf Abjad) | P4: Kode Penyebab risiko | Q4: Penyebab risiko | R4: Key Risk Indicators | S4: Unit Satuan KRI | T4: Kategori Threshold KRI | W4: Jenis Existing Control | X4: Existing Control | Y4: Penilaian Efektivitas Kontrol | Z4: Kategori Dampak | AA4: Deskripsi Dampak | AB4: Perkiraan Waktu Terpapar Risiko | AC4: Asumsi Perhitungan Dampak Kuantitatif / Penjelasan Dampak Kualitatif | AD4: Nilai Dampak | AF4: Skala Dampak | AG4: Nilai Probabilitas (Sesuai dengan Sheet Justifikasi) | AH4: Skala Probabilitas | AI4: Nilai Eksposur Risiko | AJ4: Skala Risiko | AK4: Level Nilai Risiko | AS4: BUMN | BA4: BUMN | BI4: BUMN | BM4: BUMN | BQ4: KBUMN | BU4: Jenis Data | BV4: Number | BW4: Dropdown list | BX4: Formula | BY4: Number | BZ4: Alphabet | CA4: Formula | CB4: Dropdown list | CC4: Multiple List | CD4: Free Text | CE4: Free Text | CF4: Nilai full mata uang dalam Rupiah/mata uang fungsional pembukuan | CG4: Dropdown List | CH4: Free Text | CI4: Dropdown List | CJ4: Free Text | CK4: Numerik (diisi nilai 1 jika mitgasi dilakukan pada bulan tertentu)
T5: Aman | U5: Hati-Hati | V5: Bahaya | AD5: TIDAK / WAJIB | AE5: Rupiah (Hasil Perhitungan dari sheet Justifikasi) | AF5: BUMN | AH5: BUMN | AJ5: BUMN | AK5: BUMN | AO5: Q1 | AP5: Q2 | AQ5: Q3 | AR5: Q4 | AS5: Q1 | AT5: Q2 | AU5: Q3 | AV5: Q4 | AW5: Q1 | AX5: Q2 | AY5: Q3 | AZ5: Q4 | BA5: Q1 | BB5: Q2 | BC5: Q3 | BD5: Q4 | BE5: Q1 | BF5: Q2 | BG5: Q3 | BH5: Q4 | BI5: Q1 | BJ5: Q2 | BK5: Q3 | BL5: Q4 | BM5: Q1 | BN5: Q2 | BO5: Q3 | BP5: Q4 | BQ5: Q1 | BR5: Q2 | BS5: Q3 | BT5: Q4 | BU5: Petunjuk | BY5: Kolom ini tidak perlu diisi. Akan diisi oleh Kementerian BUMN | BZ5: Diisi dengan nomor urutan penyebab risiko | CA5: Diisi dengan penyebab risiko yang ada pada tabel profil risiko | CB5: Diisi dengan pilihan: - Transfer/sharing - Reduce/mitigate - Accept/monitor - Avoid/hindari | CC5: Diisi dengan pilihan jenis rencana perlakuan risiko: - Peningkatan Kecukupan Desain Control - Peningkatan Efektivitas Pelaksanaan Control - Perbaikan Melalui Breakthrough Project - Lainnya | CD5: 1. Setiap perlakuan risiko di-break down dalam aktivitas-aktivitas yang lebih detail 2. [rule] Setiap unique ID penyebab risiko memiliki minimal 1 perlakuan risiko | CE5: Diisi dengan output atas masing-masing aktivitas rencana perlakuan risiko | CF5: Diisi dengan anggaran dalam pelaksanaan perlakuan risiko | CI5: Anggaran biaya perlakuan risiko telah dimasukkan dalam salah satu jenis program RKAP, dengan pilihan: - Pemasaran dan penjualan - Pengadaan - Produksi dan Kualitas Produk - Teknis dan Teknologi - Keuangan dan Akuntansi - Sistem dan Organisasi - Pengembangan SDM - Penelitian dan Pengembangan - Pelestarian Lingkungan - Investasi - Lainnya | CJ5: Unit penanggung jawab perlakuan risiko setingkat BOD | CK5: Terhadap masing-masing perlakuan risiko per penyebab risiko, agar diisi timeline rencana implementasinya. Apabila perlakuan risiko berlangsung sepanjang tahun, maka timeline harus diisi setiap bulan
A6: Jenis Data | B6: Number | C6: Dropdown list | D6: Number | E6: Drowdown | F6: Free Text | H6: Drowdown | J6: Dropdown list | K6: Dropdown list | L6: Number | M6: Free Text (Wajib Isi) | N6: Free Text (Wajib Isi) | O6: Alphabet | P6: Formula | Q6: Free Text | R6: Free Text/Ratio/Number | S6: Free Text/Ratio/Number | T6: Free Text/Ratio/Number | U6: Free Text/Ratio/Number | V6: Free Text/Ratio/Number | W6: Dropdown List | X6: Free Text | Y6: Dropdown list | Z6: Dropdown list | AA6: Free Text | AB6: Free Text | AC6: Free Text | AF6: Dropdown list | AG6: % | AH6: Dropdown list | AJ6: Skala 1-25 | AK6: Free Text | AO6: Nilai full mata uang dalam Rupiah/mata uang fungsional pembukuan | AS6: Dropdown list | AW6: % | BA6: Dropdown list | BE6: Nilai full mata uang dalam Rupiah/mata uang fungsional pembukuan | BI6: Skala 1-25 | BM6: Free Text | BQ6: Formula | BU6: Notes | CA6: Nama penyebab risiko harus sama persis dengan nama penyebab risiko yang ada pada tabel profil risiko | CC6: Pilihan dapat lebih dari satu | CD6: 1. Setiap penyebab risiko memiliki rencana perlakuan risiko. 2. Rencana perlakuan risiko harus spesifik dan tidak memungkinkan akan sama untuk menyelesaikan setiap penyebab. 3. Apabila satu perlakuan risiko dapat menyelesaikan lebih dari satu penyebab, artinya penyebab-penyebab tersebut belum diidentifikasi secara mendalam untuk mendapatkan akar penyebabnya.
A7: Petunjuk | E7: Kolom ini tidak perlu diisi. Akan diisi oleh Kementerian BUMN | F7: Diisi sesuai dengan sasaran BUMN | H7: Diisi sesuai dengan sasaran BUMN | J7: Diisi dengan pilihan sasaran Kementerian BUMN yang meliputi: 1) Nilai ekonomi dan sosial; 2) Inovasi bisnis model; 3) Kepemimpinan teknologi; 4) Peningkatan investasi; dan 5) Pengembangan talenta. | K7: Diisi dengan pilihan kategori risiko Portofolio BUMN Kementerian BUMN berikut: 1. Risiko Fiskal - Dividen 2. Risiko Fiskal - PMN 3. Risiko Fiskal - Subsidi & Kompensasi 4. Risiko Kebijakan - SDM 5. Risiko Kebijakan - Sektoral 6. Risiko Komposisi - Konsentrasi Portofolio 7. Risiko Struktur - Struktur Korporasi 8. Risiko Restrukturisasi & Reorganisasi - Penggabungan, Pengambilalihan, Peleburan, Pemisahan, Pembubaran, Likuidasi, Kemitraan, dan Restrukturisasi 9. Risiko Industri Umum - Formulasi Strategis 10. Risiko Industri Umum - Pasar & Makroekonomi 11. Risiko Industri Umum - Keuangan 12. Risiko Industri Umum - Reputasi & Kepatuhan 13. Risiko Industri Umum - Proyek 14. Risiko Industri Umum - Teknologi & Keamanan Siber 15. Risiko Industri Umum - Sosial & Lingkungan 16. Risiko Industri Umum - Operasional 17. Risiko Industri Perbankan - Kredit 18. Risiko Industri Perbankan - Likuiditas 19. Risiko Industri Asuransi - Investasi 20. Risiko Industri Asuransi - Aktuarial | L7: Diisi dengan nomor urutan risiko | M7: Diisi dengan peristiwa risiko yang relevan. | N7: Penjelasan /narasi atas peristiwa risiko | O7: Diisi dengan nomor urutan penyebab risiko | P7: Kodifikasi untuk penyebab risiko (Setiap penyebab risiko diberikan unique ID, misal PTPI - 1. xxx") | Q7: Diisi penyebab risiko secara jelas. BUMN dapat menggali berbagai penyebab risiko. Sebagai contoh dapat melihat dari berbagai segi: people, process, network, maupun system. | R7: Setiap peristiwa risiko harus memiliki minimal satu KRI | S7: Unit satuan KRI bisa berbentuk amount,/percentage/range/kualitatif | T7: Diisi sesuai dengan batasan yang ditetapkan oleh masing-masing BUMN | W7: Diisi dengan pilihan pada hirarki pertama: - Kontrol operasi - Kontrol kepatuhan (compliance) - Kontrol pelaporan Setelah hirarki pertama dipilih, dilanjutkan dengan pilihan hirarki kedua: - Kontrol pada level entitas/kantor pusat - Kontral pada level operasi | X7: BUMN dapat mengisikan semua existing control yang relevan terhadap suatu risiko. Existing control tersebut dapat berupa kontrol SOP, sistem, kebijakan, dll | Y7: Diisi dengan penilaian terhadap efektivitas kontrol saat ini (existing control) dengan pilihan sebagai berikut: 1) Cukup dan Efektif; 2) Cukup dan Efektif Sebagian; 3) Cukup dan Tidak Efektif; 4) Tidak Cukup dan Efektif Sebagian; dan 5) Tidak Cukup dan Tidak Efektif. | Z7: Diisi dengan pilihan kategori dampak: - Dampak kuantitatif - Dampak kualitatif | AA7: Disi dengan penjelasan/deskripsi atas dampak yang akan diterima apabila risiko terjadi. | AB7: Diisi dengan perkiraan periode waktu BUMN terpapar Risiko, sesuai dengan karakter Risiko tersebut. Perkiraan waktu diidentifikasi melalui proyeksi, data historis, maupun keumuman pada industri BUMN terkait
A8: Notes | F8: Sasaran disusun secara lengkap. Sebagai contoh: "Peningkatan market share segmen corporate dari 20% menjadi 30% pada akhir tahun 2024" | H8: Sasaran disusun secara lengkap. Sebagai contoh: "Peningkatan market share segmen corporate dari 20% menjadi 30% pada akhir tahun 2024" | K8: - Risiko pada Industri Umum tidak boleh dipetakan dalam kategori Risiko Industri Perbankan dan Asuransi - Risiko pada Industri perbankan & asuransi dapat dipetakan dalam kategori Risiko Industri Umum | L8: 1. Nomor risiko harus konsisten pada saat pelaporan. 2. Apabila terdapat risiko yang bertambah maka nomornya melanjutkan sesuai dengan urutan terakhir | M8: Risiko harus diidentifikasi dengan tepat, dan memenuhi ketentuan: - Bukan negasi sasaran - Dipetakan dalam fault tree analysis dan yang menjadi risk event yang paling mendekati dengan sumber utama penyebab risiko. | P8: Setiap penyebab kejadian diberikan unique ID | Q8: Jika satu Risiko memiliki lebih dari satu penyebab Risiko, maka dituliskan dalam cell di baris berikutnya (tidak digabung menjadi satu cell). | R8: Kriteria memilih KRI : 1. Penyebab risiko yang paling utama 2. Paling tersedia data historisnya & dapat diintegrasikan 3. Relevan terhadap penyebab masalah 4. Prediktor perubahan profil risiko 5. Mudah diinterpretasikan, dipahami & dipantau 6. Relatif terhadap keefektifan biaya | V8: ≤ | W8: Apabila jenis existing control memiliki lebih dari satu jenis control, maka dituliskan dalam cell di baris berikutnya (tidak digabung menjadi satu cell). | X8: Apabila existing control lebih dari 1, untuk control ke 2 dst agar ditambahkan pada row di bawahnya | Y8: (Dalam memilih lihat sheet"kriteria efektivitas kontrol") | Z8: 1) Dampak kuantitatif: Risiko yang memiliki dampak finansial terhadap pencapaian target laba BUMN. 2) Dampak kualitatif: Risiko yang tidak memiliki dampak finansial terhadap pencapaian target laba BUMN. | AB8: Periode waktu dapat berupa range bulan (contoh Januari 2023 – Februari 2024)
AF9: =AE13/AI3 -> 0.16825731 | AO9: =AO13/$AI$3 -> 0.16825731 | AP9: =AP13/$AI$3 -> 0.16825731 | AQ9: =AQ13/$AI$3 -> 0.16825731 | AR9: =AR13/$AI$3 -> 0.16825731
A10: Contoh | B10: 1 | C10: PT Perusahaan Listrik Negara (Persero) | D10: PLN BATAM | E10: BID KEU | G10: 1 | H10: Pencapaian Biaya Pokok Penjualan (BPP) Non MPP (Rp/kWh) Rp 1.453,13 | I10: 1. Nilai ekonomi dan sosial | J10: 3.6.11 Peristiwa Risiko terkait keuangan | K10: 4. Risiko Kebijakan - SDM | L10: 1 | M10: Kenaikan beban operasi akibat pelemahan nilai tukar rupiah terhadap dollar | N10: Terdapat beban operasi PLN Batam yang menggunakan mata uang asing dalam proses pembayaran atau mengacu atas besaran kurs rupiah terhadap dollar sebagai bagian perhitungan besaran tagihan | O10: a | P10: =CONCATENATE(E10,"-",L10,"-",O10) -> BID KEU-1-a | Q10: Faktor eksternal perusahaan seperti kondisi ekonomi politik dalam negeri dan atau luar negeri, dan tingkat kebutuhan pasar akan mata uang dollar | R10: Nilai tukar rupiah terhadap dollar | S10: Rupiah | T10: 13.438 Rp/USD | U10: 13.439 Rp/USD sd 16.874 Rp/USD | V10: > 16.875 Rp/USD | W10: Kontrol operasi - level operasi | X10: Memonitor nilai tukar rupiah terhadap dollar | Y10: 1. Cukup dan Efektif | Z10: Kuantitatif | AA10: D1. Terganggunya likuiditas perusahaan D2. Biaya melebihi target RKAP D3. Pembayaran pokok dan bunga lebih tinggi dari RKAP | AB10: Maret-Des 2024 | AC10: Dari nilai tukar rupiah terhadap kurs untuk pembayaran biaya operasional dan beban bunga perusahaan | AD10: =IF(Z10="KUANTITATIF","Wajib Isi","Tidak Wajib") -> Wajib Isi | AE10: 100000000 | AF10: 4 | AG10: 0.67 | AH10: 1 | AI10: =IF(Z10="kuantitatif",(AE10*AG10),(AF10*AH10*1%*$AI$3)) -> 67000000 | AJ10: =INDEX(Source!$E$33:$I$37,MATCH(AH10,Source!$D$33:$D$37,0),MATCH(AF10,Source!$E$38:$I$38,0)) -> 15 | AK10: =LOOKUP(MATCH(AJ10,'Perhitungan Heatmap'!$D$9:$AB$9),'Perhitungan Heatmap'!$D$9:$AB$9,'Perhitungan Heatmap'!$D$10:$AB$10) -> Moderate | AS10: 3 | AT10: 5 | AU10: 3 | AV10: 2 | BA10: 2 | BB10: 4 | BC10: 3 | BD10: 3 | BI10: =INDEX(Source!$E$33:$I$37,MATCH(BA10,Source!$D$33:$D$37,0),MATCH(AS10,Source!$E$38:$I$38,0)) -> 11 | BJ10: =INDEX(Source!$E$33:$I$37,MATCH(BB10,Source!$D$33:$D$37,0),MATCH(AT10,Source!$E$38:$I$38,0)) -> 24 | BK10: =INDEX(Source!$E$33:$I$37,MATCH(BC10,Source!$D$33:$D$37,0),MATCH(AU10,Source!$E$38:$I$38,0)) -> 13 | BL10: =INDEX(Source!$E$33:$I$37,MATCH(BD10,Source!$D$33:$D$37,0),MATCH(AV10,Source!$E$38:$I$38,0)) -> 8 | BM10: =LOOKUP(MATCH(BI10,'Perhitungan Heatmap'!$D$9:$AB$9),'Perhitungan Heatmap'!$D$9:$AB$9,'Perhitungan Heatmap'!$D$10:$AB$10) -> Low To Moderate | BN10: =LOOKUP(MATCH(BJ10,'Perhitungan Heatmap'!$D$9:$AB$9),'Perhitungan Heatmap'!$D$9:$AB$9,'Perhitungan Heatmap'!$D$10:$AB$10) -> High | BO10: =LOOKUP(MATCH(BK10,'Perhitungan Heatmap'!$D$9:$AB$9),'Perhitungan Heatmap'!$D$9:$AB$9,'Perhitungan Heatmap'!$D$10:$AB$10) -> Moderate | BP10: =LOOKUP(MATCH(BL10,'Perhitungan Heatmap'!$D$9:$AB$9),'Perhitungan Heatmap'!$D$9:$AB$9,'Perhitungan Heatmap'!$D$10:$AB$10) -> Low To Moderate | BY10: =L10 -> 1 | BZ10: =O10 -> a | CA10: =Q10 -> Faktor eksternal perusahaan seperti kondisi ekonomi politik dalam negeri dan atau luar negeri, dan tingkat kebutuhan pasar akan mata uang dollar | CB10: Reduce/Mitigate | CC10: Peningkatan Efektivitas Pelaksanaan Control | CD10: 1. Kegiatan pemasaran menggunakan integrated marketing channel secara offline dan online 2. Mengakuisisi captive power 3. Melaksanakan akselerasi layanan pelanggan dan calon pelanggan potensial dengan upaya terobosan dalam percepatan nota kesepakatan, percepatan pembayaran dan percepatan penyalaan 4. Mendorong tambah daya bagi pelanggan retail (TR) yang jam nyala minimumnya ? 400-600 jam. | CE10: Jumlah program pemasaran | CF10: 292092000000 | CG10: Anggaran Kas Investasi | CI10: Pengadaan | CJ10: DIR AGA | CU10: 1 | CV10: 1
A11: Start Pengisian | B11: 1 | C11: PT Perusahaan Listrik Negara (Persero) | D11: PLN BATAM | E11: BID AGA | H11: Pendapatan Penjualan Tenaga Listrik TUL 309 PLN Batam sebesar Rp 7.951.21 Milyar | I11: 1. Nilai ekonomi dan sosial | J11: 3.6.16 Peristiwa Risiko terkait operasional | K11: 11. Risiko Industri Umum - Keuangan | L11: 1 | M11: Mundurnya atau batalnya aktivasi daya potensi pelanggan yang telah diperhitungkan dalam RKAP | N11: Terdapat permintaan penyambungan atau aktivasi daya dari calon pelanggan dan pelanggan dalam jumlah besar yang akan masuk ke Batam pada tahun 2026 sebesar 92,1 MVA, namun belum dapat dipastikan apakah calon pelanggan akan melakukan aktivasi sesuai rencana penyambungan dalam perjanjian dan lama berlangganan | O11: a | P11: =CONCATENATE(E11,"-",L11,"-",O11) -> BID AGA-1-a | Q11: Belum siapnya infrastruktur pelanggan | R11: Jumlah pendapatan TL | S11: Rupiah | T11: >7.951.21 Milyar | U11: 7.951.21 Milyar | V11: <7.951.21 Milyar | W11: Kontrol operasi - level operasi | X11: Cash War Room (CWR) | Y11: 1. Cukup dan Efektif | Z11: Kuantitatif | AA11: Pendapatan penjualan listrik di bawah target | AB11: Januari s.d Desember 2026 | AC11: Nilai Dampak dihitung dari proyeksi penjualan 2026 dan probability dihitung dari % calon pelanggan / pelanggan batal/mundur | AD11: =IF(Z11="KUANTITATIF","Wajib Isi","Tidak Wajib") -> Wajib Isi | AE11: ='Justifikasi Risk Assessment'!P40 -> 660636000000 | AF11: 5 | AG11: ='Justifikasi Risk Assessment'!D52 -> 0.6 | AH11: 4 | AI11: =IF(Z11="kuantitatif",(AE11*AG11),(AF11*AH11*1%*$AI$3)) -> 396381600000 | AJ11: =INDEX(Source!$E$33:$I$37,MATCH(AH11,Source!$D$33:$D$37,0),MATCH(AF11,Source!$E$38:$I$38,0)) -> 24 | AK11: =LOOKUP(MATCH(AJ11,'Perhitungan Heatmap'!$D$9:$AB$9),'Perhitungan Heatmap'!$D$9:$AB$9,'Perhitungan Heatmap'!$D$10:$AB$10) -> High | AO11: =AE11 -> 660636000000 | AP11: ='Justifikasi Risk Assessment'!R42 -> 585357000000 | AQ11: ='Justifikasi Risk Assessment'!S42 -> 410748000000 | AR11: ='Justifikasi Risk Assessment'!T42 -> 213579000000 | AS11: 5 | AT11: 5 | AU11: 4 | AV11: 2 | AW11: =AG11 -> 0.6 | AX11: =AW11*75% -> 0.45 | AY11: =AX11*75% -> 0.3375 | AZ11: =AY11*75% -> 0.253125 | BA11: 4 | BB11: 3 | BC11: 2 | BD11: 2 | BE11: =AO11*AW11 -> 396381600000 | BF11: =AP11*AX11 -> 2.6341065e+11 | BG11: =AQ11*AY11 -> 138627450000 | BH11: =AR11*AZ11 -> 54062184375 | BI11: =INDEX(Source!$E$33:$I$37,MATCH(BA11,Source!$D$33:$D$37,0),MATCH(AS11,Source!$E$38:$I$38,0)) -> 24 | BJ11: =INDEX(Source!$E$33:$I$37,MATCH(BB11,Source!$D$33:$D$37,0),MATCH(AT11,Source!$E$38:$I$38,0)) -> 23 | BK11: =INDEX(Source!$E$33:$I$37,MATCH(BC11,Source!$D$33:$D$37,0),MATCH(AU11,Source!$E$38:$I$38,0)) -> 16 | BL11: =INDEX(Source!$E$33:$I$37,MATCH(BD11,Source!$D$33:$D$37,0),MATCH(AV11,Source!$E$38:$I$38,0)) -> 6 | BM11: =LOOKUP(MATCH(BI11,'Perhitungan Heatmap'!$D$9:$AB$9),'Perhitungan Heatmap'!$D$9:$AB$9,'Perhitungan Heatmap'!$D$10:$AB$10) -> High | BN11: =LOOKUP(MATCH(BJ11,'Perhitungan Heatmap'!$D$9:$AB$9),'Perhitungan Heatmap'!$D$9:$AB$9,'Perhitungan Heatmap'!$D$10:$AB$10) -> High | BO11: =LOOKUP(MATCH(BK11,'Perhitungan Heatmap'!$D$9:$AB$9),'Perhitungan Heatmap'!$D$9:$AB$9,'Perhitungan Heatmap'!$D$10:$AB$10) -> Moderate To High | BP11: =LOOKUP(MATCH(BL11,'Perhitungan Heatmap'!$D$9:$AB$9),'Perhitungan Heatmap'!$D$9:$AB$9,'Perhitungan Heatmap'!$D$10:$AB$10) -> Low To Moderate | CB11: Reduce/Mitigate | CC11: Peningkatan Efektivitas Pelaksanaan Control | CD11: 1. Penagihan e-min sebesar 50 jam nyala sesuai tahapan aktivasi daya | CE11: Surat penagihan e-min kepada calon pelanggan | CJ11: VP AGA | CK11: 1 | CL11: 1 | CM11: 1 | CN11: 1 | CO11: 1 | CP11: 1 | CQ11: 1 | CR11: 1 | CS11: 1 | CT11: 1 | CU11: 1 | CV11: 1
B12: 2 | C12: PT Perusahaan Listrik Negara (Persero) | D12: PLN BATAM | E12: BID AGA | H12: Optimalisasi Biaya Operasi | I12: 1. Nilai ekonomi dan sosial | J12: 3.6.11 Peristiwa Risiko terkait keuangan | K12: 11. Risiko Industri Umum - Keuangan | L12: 2 | M12: Realisasi Biaya Operasi melampaui Pagu anggaran yang ditetapkan dalam RKAP | N12: Terdapat penambahan program layanan yang belum direncanakan pada saat penyusunan Anggaran Operasi, sehingga menimbulkan penambahan kebutuhan Anggaran Operasi | O12: a | P12: =CONCATENATE(E12,"-",L12,"-",O12) -> BID AGA-2-a | Q12: Adanya program pemasaran/produk layanan baru yang belum direncanakan dan masuk dalam RKAP | R12: Realisasi SKAO | S12: % | T12: <100% | U12: 1 | V12: >100% | W12: Kontrol operasi - level operasi | X12: SK Pengadaan Barang dan Jasa SK Pengendalian Anggaran | Y12: 1. Cukup dan Efektif | Z12: Kuantitatif | AA12: Biaya Operasi melebihi pagu anggaran | AB12: Juli s.d Desember 2026 | AC12: Nilai Dampak dan probabilitas diambil dari nilai tengah atau rata-rata selisih AO selama 2021-2025 | AD12: =IF(Z12="KUANTITATIF","Wajib Isi","Tidak Wajib") -> Wajib Isi | AE12: ='Justifikasi Risk Assessment'!G65 -> 3600000000 | AF12: 1 | AG12: ='Justifikasi Risk Assessment'!J60 -> 0.2 | AH12: 2 | AI12: =IF(Z12="kuantitatif",(AE12*AG12),(AF12*AH12*1%*$AI$3)) -> 720000000 | AJ12: =INDEX(Source!$E$33:$I$37,MATCH(AH12,Source!$D$33:$D$37,0),MATCH(AF12,Source!$E$38:$I$38,0)) -> 2 | AK12: =LOOKUP(MATCH(AJ12,'Perhitungan Heatmap'!$D$9:$AB$9),'Perhitungan Heatmap'!$D$9:$AB$9,'Perhitungan Heatmap'!$D$10:$AB$10) -> Low | AO12: =AE12 -> 3600000000 | AP12: =AO12*75% -> 2700000000 | AQ12: =AO12*50% -> 1800000000 | AR12: =AO12*25% -> 900000000 | AS12: 1 | AT12: 1 | AU12: 1 | AV12: 1 | AW12: =AG12 -> 0.2 | AX12: =AW12*75% -> 0.15 | AY12: =AX12*75% -> 0.1125 | AZ12: =AY12*75% -> 0.084375 | BA12: 2 | BB12: 2 | BC12: 2 | BD12: 1 | BE12: =AO12*AW12 -> 720000000 | BF12: =AP12*AX12 -> 4.05e+08 | BG12: =AQ12*AY12 -> 2.025e+08 | BH12: =AR12*AZ12 -> 75937500 | BI12: =INDEX(Source!$E$33:$I$37,MATCH(BA12,Source!$D$33:$D$37,0),MATCH(AS12,Source!$E$38:$I$38,0)) -> 2 | BJ12: =INDEX(Source!$E$33:$I$37,MATCH(BB12,Source!$D$33:$D$37,0),MATCH(AT12,Source!$E$38:$I$38,0)) -> 2 | BK12: =INDEX(Source!$E$33:$I$37,MATCH(BC12,Source!$D$33:$D$37,0),MATCH(AU12,Source!$E$38:$I$38,0)) -> 2 | BL12: =INDEX(Source!$E$33:$I$37,MATCH(BD12,Source!$D$33:$D$37,0),MATCH(AV12,Source!$E$38:$I$38,0)) -> 1 | BM12: =LOOKUP(MATCH(BI12,'Perhitungan Heatmap'!$D$9:$AB$9),'Perhitungan Heatmap'!$D$9:$AB$9,'Perhitungan Heatmap'!$D$10:$AB$10) -> Low | BN12: =LOOKUP(MATCH(BJ12,'Perhitungan Heatmap'!$D$9:$AB$9),'Perhitungan Heatmap'!$D$9:$AB$9,'Perhitungan Heatmap'!$D$10:$AB$10) -> Low | BO12: =LOOKUP(MATCH(BK12,'Perhitungan Heatmap'!$D$9:$AB$9),'Perhitungan Heatmap'!$D$9:$AB$9,'Perhitungan Heatmap'!$D$10:$AB$10) -> Low | BP12: =LOOKUP(MATCH(BL12,'Perhitungan Heatmap'!$D$9:$AB$9),'Perhitungan Heatmap'!$D$9:$AB$9,'Perhitungan Heatmap'!$D$10:$AB$10) -> Low | CB12: Accept/Monitor | CC12: Peningkatan Efektivitas Pelaksanaan Control | CD12: 1. Memastikan penggunaan anggaran operasi sesuai dengan program kerja yang telah ditetapkan. 2. Melakukan monitoring penggunaan anggaran operasi setiap bulannya 3. Melakukan evaluasi atas rencana penggunaan anggaran operasi dengan memperhatikan tingkat urgensi | CE12: Daftar Produk Layanan beserta anggaran | CI12: Pemasaran dan penjualan | CJ12: VP AGA | CK12: 1 | CL12: 1 | CM12: 1 | CN12: 1 | CO12: 1 | CP12: 1 | CQ12: 1 | CR12: 1 | CS12: 1 | CT12: 1 | CU12: 1 | CV12: 1
B13: 3 | C13: PT Perusahaan Listrik Negara (Persero) | D13: PLN BATAM | E13: BID AGA | H13: Periode Pengumpulan Piutang (Collection Period) | I13: 1. Nilai ekonomi dan sosial | J13: 3.6.11 Peristiwa Risiko terkait keuangan | K13: 11. Risiko Industri Umum - Keuangan | L13: 3 | M13: Keterlambatan Pembayaran tagihan interkoneksi | N13: Dalam kurun waktu tahun 2023 sampai dengan 2025 realisasi keterlambatan Penerimaan Pembayaran Tagihan Interkoneksi Bintan, Sembulang, Belakang Padang dan Buluh lebih dari 35 adalah sebanyak 16 bulan dari 36 bulan | O13: a | P13: =CONCATENATE(E13,"-",L13,"-",O13) -> BID AGA-3-a | Q13: Dokumen penagihan terlambat di submit pada aplikasi Vendor Invoice Portal (VIP), dikarenakan SKAO PLN UID RKR belum terbit | R13: Realisasi Periode Pengumpulan Piutang | S13: hari kalender | T13: <35 hari | U13: 35 hari | V13: >35 hari | W13: Kontrol operasi - level operasi | X13: PJBTL Interkoneksi antara PLN UID RKR dengan PLN Batam | Y13: 2. Cukup dan Efektif Sebagian | Z13: Kuantitatif | AA13: Realisasi atas Penerimaan Pendapatan Interkoneksi tidak sesuai dengan target penerimaan | AB13: Januari s.d Desember 2026 | AC13: Rata-rata keterlambatan penerimaan arus kas | AD13: =IF(Z13="KUANTITATIF","Wajib Isi","Tidak Wajib") -> Wajib Isi | AE13: ='Justifikasi Risk Assessment'!H89 -> 1.0263696e+11 | AF13: 1 | AG13: ='Justifikasi Risk Assessment'!H90 -> 0.44444444 | AH13: 3 | AI13: =IF(Z13="kuantitatif",(AE13*AG13),(AF13*AH13*1%*$AI$3)) -> 4.5616425e+10 | AJ13: =INDEX(Source!$E$33:$I$37,MATCH(AH13,Source!$D$33:$D$37,0),MATCH(AF13,Source!$E$38:$I$38,0)) -> 3 | AK13: =LOOKUP(MATCH(AJ13,'Perhitungan Heatmap'!$D$9:$AB$9),'Perhitungan Heatmap'!$D$9:$AB$9,'Perhitungan Heatmap'!$D$10:$AB$10) -> Low | AO13: =AE13 -> 1.0263696e+11 | AP13: =AO13 -> 1.0263696e+11 | AQ13: =AP13 -> 1.0263696e+11 | AR13: =AQ13 -> 1.0263696e+11 | AS13: 1 | AT13: 1 | AU13: 1 | AV13: 1 | AW13: =AG13 -> 0.44444444 | AX13: =AW13*75% -> 0.33333333 | AY13: =AX13*75% -> 0.25 | AZ13: =AY13*75% -> 0.1875 | BA13: 3 | BB13: 2 | BC13: 2 | BD13: 1 | BE13: =AO13*AW13 -> 4.5616425e+10 | BF13: =AP13*AX13 -> 3.4212319e+10 | BG13: =AQ13*AY13 -> 2.5659239e+10 | BH13: =AR13*AZ13 -> 1.9244429e+10 | BI13: =INDEX(Source!$E$33:$I$37,MATCH(BA13,Source!$D$33:$D$37,0),MATCH(AS13,Source!$E$38:$I$38,0)) -> 3 | BJ13: =INDEX(Source!$E$33:$I$37,MATCH(BB13,Source!$D$33:$D$37,0),MATCH(AT13,Source!$E$38:$I$38,0)) -> 2 | BK13: =INDEX(Source!$E$33:$I$37,MATCH(BC13,Source!$D$33:$D$37,0),MATCH(AU13,Source!$E$38:$I$38,0)) -> 2 | BL13: =INDEX(Source!$E$33:$I$37,MATCH(BD13,Source!$D$33:$D$37,0),MATCH(AV13,Source!$E$38:$I$38,0)) -> 1 | BM13: =LOOKUP(MATCH(BI13,'Perhitungan Heatmap'!$D$9:$AB$9),'Perhitungan Heatmap'!$D$9:$AB$9,'Perhitungan Heatmap'!$D$10:$AB$10) -> Low | BN13: =LOOKUP(MATCH(BJ13,'Perhitungan Heatmap'!$D$9:$AB$9),'Perhitungan Heatmap'!$D$9:$AB$9,'Perhitungan Heatmap'!$D$10:$AB$10) -> Low | BO13: =LOOKUP(MATCH(BK13,'Perhitungan Heatmap'!$D$9:$AB$9),'Perhitungan Heatmap'!$D$9:$AB$9,'Perhitungan Heatmap'!$D$10:$AB$10) -> Low | BP13: =LOOKUP(MATCH(BL13,'Perhitungan Heatmap'!$D$9:$AB$9),'Perhitungan Heatmap'!$D$9:$AB$9,'Perhitungan Heatmap'!$D$10:$AB$10) -> Low | CB13: Accept/Monitor | CC13: Peningkatan Efektivitas Pelaksanaan Control | CD13: 1. Memastikan pelaksanaan pembacaan meter tanggal 1 pukul 10 setiap bulannya. 2. Berkoordinasi dengan Bidang Operasi untuk Memastikan terbitnya Berita Acara penyaluran tenaga listrik 3. Koordinasi dengan pihak UID untuk memastikan kecapatan proses pembayaran 2. Membuat invoice penagihan dan memastikan bahwa invoice yang diterbitkan telah sesuai dan benar. 3. Mereview secara bertingkat mulai dari MAN REV dan VP AGA atas invoice penagihan dan lampirannya. 4. Melakukan pengiriman invoice tagihan via Pos 5. Menghubungi pihak RKR untuk memastikan invoice tagihan telah diterima 6. Melakukan sales call secara rutin dengan pihak RKR untuk memastikan pembayaran | CE13: 1. Invoice tagihan Penjualan Listrik ke RKR 2. Bukti koordinasi via email, atau WA atau media lain. | CF13: 50000000 | CJ13: VP AGA | CK13: 1 | CL13: 1 | CM13: 1 | CN13: 1 | CO13: 1 | CP13: 1 | CQ13: 1 | CR13: 1 | CS13: 1 | CT13: 1 | CU13: 1 | CV13: 1
B14: 4 | C14: PT Perusahaan Listrik Negara (Persero) | D14: PLN BATAM | E14: BID AGA | H14: Penyediaan Tenaga Listrik Pelanggan Additional Demand | I14: 1. Nilai ekonomi dan sosial | J14: 3.6.11 Peristiwa Risiko terkait keuangan | K14: 16. Risiko Industri Umum - Operasional | L14: 4 | M14: Calon Pelanggan Additional Demand batal menjadi pelanggan | N14: Terdapat permintaan additional demand dari calon pelanggan dalam jumlah besar yang akan masuk ke Batam pada tahun 2026 sebesar 203,5 MVA., namun belum dapat dipastikan apakah calon pelanggan akan melakukan aktivasi sesuai rencana penyambungan dalam perjanjian dan lama berlangganan | O14: a | P14: =CONCATENATE(E14,"-",L14,"-",O14) -> BID AGA-4-a | Q14: 1. Tidak mencapai kesepakatan tarif dengan calon pelanggan 2. Calon pelanggan memilih investasi diluar Batam | R14: Penandatangan PJBTL/ Amandemen PJBTL | S14: % | T14: <100% | U14: 1 | V14: >100% | W14: Kontrol operasi - level operasi | X14: Penandatanganan PJBTL/Amandemen PJBTL dengan Pelanggan Add Demand | Y14: 2. Cukup dan Efektif Sebagian | Z14: Kuantitatif | AA14: Potensi tambahan pendapatan dari calon pelanggan additional demand tidak tercapai | AB14: September s.d Desember 2026 | AC14: Dihitung berdasarkan kapasitas pelanggan dikali jam nyala minimum, dikali tarif dikali durasi kontrak selama tahun 2026 | AD14: =IF(Z14="KUANTITATIF","Wajib Isi","Tidak Wajib") -> Wajib Isi | AE14: ='Justifikasi Risk Assessment'!P112 -> 254880000000 | AF14: 3 | AG14: ='Justifikasi Risk Assessment'!D124 -> 0.33333333 | AH14: 2 | AI14: =IF(Z14="kuantitatif",(AE14*AG14),(AF14*AH14*1%*$AI$3)) -> 84960000000 | AJ14: =INDEX(Source!$E$33:$I$37,MATCH(AH14,Source!$D$33:$D$37,0),MATCH(AF14,Source!$E$38:$I$38,0)) -> 11 | AK14: =LOOKUP(MATCH(AJ14,'Perhitungan Heatmap'!$D$9:$AB$9),'Perhitungan Heatmap'!$D$9:$AB$9,'Perhitungan Heatmap'!$D$10:$AB$10) -> Low To Moderate | AO14: ='Justifikasi Risk Assessment'!Q114 -> 254880000000 | AP14: ='Justifikasi Risk Assessment'!R114 -> 254880000000 | AQ14: ='Justifikasi Risk Assessment'!S114 -> 254880000000 | AR14: ='Justifikasi Risk Assessment'!T114 -> 191160000000 | AS14: 2 | AT14: 2 | AU14: 2 | AV14: 1 | AW14: =AG14 -> 0.33333333 | AX14: =AW14*75% -> 0.25 | AY14: =AW14*50% -> 0.16666667 | AZ14: =AW14*25% -> 0.083333333 | BA14: 2 | BB14: 1 | BC14: 1 | BD14: 1 | BE14: =AO14*AW14 -> 84960000000 | BF14: =AP14*AX14 -> 63720000000 | BG14: =AQ14*AY14 -> 42480000000 | BH14: =AR14*AZ14 -> 15930000000 | BI14: =INDEX(Source!$E$33:$I$37,MATCH(BA14,Source!$D$33:$D$37,0),MATCH(AS14,Source!$E$38:$I$38,0)) -> 6 | BJ14: =INDEX(Source!$E$33:$I$37,MATCH(BB14,Source!$D$33:$D$37,0),MATCH(AT14,Source!$E$38:$I$38,0)) -> 5 | BK14: =INDEX(Source!$E$33:$I$37,MATCH(BC14,Source!$D$33:$D$37,0),MATCH(AU14,Source!$E$38:$I$38,0)) -> 5 | BL14: =INDEX(Source!$E$33:$I$37,MATCH(BD14,Source!$D$33:$D$37,0),MATCH(AV14,Source!$E$38:$I$38,0)) -> 1 | BM14: =LOOKUP(MATCH(BI14,'Perhitungan Heatmap'!$D$9:$AB$9),'Perhitungan Heatmap'!$D$9:$AB$9,'Perhitungan Heatmap'!$D$10:$AB$10) -> Low To Moderate | BN14: =LOOKUP(MATCH(BJ14,'Perhitungan Heatmap'!$D$9:$AB$9),'Perhitungan Heatmap'!$D$9:$AB$9,'Perhitungan Heatmap'!$D$10:$AB$10) -> Low | BO14: =LOOKUP(MATCH(BK14,'Perhitungan Heatmap'!$D$9:$AB$9),'Perhitungan Heatmap'!$D$9:$AB$9,'Perhitungan Heatmap'!$D$10:$AB$10) -> Low | BP14: =LOOKUP(MATCH(BL14,'Perhitungan Heatmap'!$D$9:$AB$9),'Perhitungan Heatmap'!$D$9:$AB$9,'Perhitungan Heatmap'!$D$10:$AB$10) -> Low | BZ14: b. | CA14: ddddhhjjk | CB14: Accept/Monitor | CC14: Peningkatan Efektivitas Pelaksanaan Control | CD14: Probing ke Pelanggan Additional Demand & memastikan penandatanganan SPJBTL dan Amandemen dengan total daya 259,9 MVA | CE14: PJBTL / Amandemen PJBTL | CI14: Pemasaran dan penjualan | CJ14: VP AGA | CS14: 1 | CT14: 1 | CU14: 1 | CV14: 1
B15: 5 | C15: PT Perusahaan Listrik Negara (Persero) | D15: PLN BATAM | E15: BID AGA | H15: Harga Jual interkoneksi 150 kV Batam-Bintan dan 20 kV On-Grid | I15: 1. Nilai ekonomi dan sosial | J15: 3.6.11 Peristiwa Risiko terkait keuangan | K15: 16. Risiko Industri Umum - Operasional | L15: 5 | M15: Tidak disetujuinya persetujuan harga jual tenaga listrik interkoneksi oleh Menteri | N15: PLN Batam mengajukan perubahan harga jual tenaga listrik interkoneksi, dimana harga jual tenaga listrik saat ini menggunakan tarif tertinggi layanan khusus sebesar Rp 2.005/kWh berdasarkan penetapan TA TW III 2025. | O15: a | P15: =CONCATENATE(E15,"-",L15,"-",O15) -> BID AGA-5-a | Q15: Kajian dan analisis harga jual belum terinformasi secara komprehensive kepada Pejabat berwenang yang memberikan persetujuan Harga Jual | R15: Persetujuan Menteri terhadap Harga Jual Listrik Batam Bintan | S15: Bulan | T15: Mei | U15: Juni | V15: Juli | W15: Kontrol operasi - level entitas/kantor pusat | X15: Koordinasi dengan PLN UID RKR terkait proses persetujuan harga jual interkoneksi | Y15: 2. Cukup dan Efektif Sebagian | Z15: Kuantitatif | AA15: HJR Batam Bintan tidak tercapai | AB15: Januari s.d Desember 2026 | AC15: Delta HJR saat ini dengan HJR usulan dikali kwh jual | AD15: =IF(Z15="KUANTITATIF","Wajib Isi","Tidak Wajib") -> Wajib Isi | AE15: ='Justifikasi Risk Assessment'!O135 -> 7.9112115e+09 | AF15: 3 | AG15: ='Justifikasi Risk Assessment'!D139 -> 0.25 | AH15: 2 | AI15: =IF(Z15="kuantitatif",(AE15*AG15),(AF15*AH15*1%*$AI$3)) -> 1.9778029e+09 | AJ15: =INDEX(Source!$E$33:$I$37,MATCH(AH15,Source!$D$33:$D$37,0),MATCH(AF15,Source!$E$38:$I$38,0)) -> 11 | AK15: =LOOKUP(MATCH(AJ15,'Perhitungan Heatmap'!$D$9:$AB$9),'Perhitungan Heatmap'!$D$9:$AB$9,'Perhitungan Heatmap'!$D$10:$AB$10) -> Low To Moderate | AO15: ='Justifikasi Risk Assessment'!Q136 -> 7.9112115e+09 | AP15: ='Justifikasi Risk Assessment'!R136 -> 6.0335038e+09 | AQ15: ='Justifikasi Risk Assessment'!S136 -> 4.0587236e+09 | AR15: ='Justifikasi Risk Assessment'!T136 -> 2.0065139e+09 | AS15: 1 | AT15: 1 | AU15: 1 | AV15: 1 | AW15: =AG15 -> 0.25 | AX15: =AW15*75% -> 0.1875 | AY15: =AW15*50% -> 0.125 | AZ15: =AW15*25% -> 0.0625 | BA15: 3 | BB15: 2 | BC15: 2 | BD15: 1 | BE15: =AO15*AW15 -> 1.9778029e+09 | BF15: =AP15*AX15 -> 1.131282e+09 | BG15: =AQ15*AY15 -> 5.0734045e+08 | BH15: =AR15*AZ15 -> 1.2540712e+08 | BI15: 1 | BJ15: 1 | BK15: 1 | BL15: 1 | BM15: =LOOKUP(MATCH(BI15,'Perhitungan Heatmap'!$D$9:$AB$9),'Perhitungan Heatmap'!$D$9:$AB$9,'Perhitungan Heatmap'!$D$10:$AB$10) -> Low | BN15: =LOOKUP(MATCH(BJ15,'Perhitungan Heatmap'!$D$9:$AB$9),'Perhitungan Heatmap'!$D$9:$AB$9,'Perhitungan Heatmap'!$D$10:$AB$10) -> Low | BO15: =LOOKUP(MATCH(BK15,'Perhitungan Heatmap'!$D$9:$AB$9),'Perhitungan Heatmap'!$D$9:$AB$9,'Perhitungan Heatmap'!$D$10:$AB$10) -> Low | BP15: =LOOKUP(MATCH(BL15,'Perhitungan Heatmap'!$D$9:$AB$9),'Perhitungan Heatmap'!$D$9:$AB$9,'Perhitungan Heatmap'!$D$10:$AB$10) -> Low | CB15: Accept/Monitor | CC15: Peningkatan Efektivitas Pelaksanaan Control | CD15: 1. Koordinasi dengan PLN UID RKR, DIV DKI, DIV APR terkait KKP, Proses GRC dan surat permohonan persetujuan harga jual tenaga listrik dari PLN Persero 2. Koordinasi dengan DJK mengenai persetujuan harga jual tenaga listrik | CE15: Notulen rapat koordinasi pembahasan | CF15: 100000000 | CJ15: VP AGA | CK15: 1 | CL15: 1 | CM15: 1 | CN15: 1 | CO15: 1 | CP15: 1 | CQ15: 1
B16: 6 | C16: PT Perusahaan Listrik Negara (Persero) | D16: PLN BATAM | E16: BID AGA | H16: Indeks Kepuasan Pelanggan | I16: 1. Nilai ekonomi dan sosial | J16: 3.6.12 Peristiwa Risiko terkait hukum, reputasi, dan kepatuhan | K16: 12. Risiko Industri Umum - Reputasi & Kepatuhan | L16: 6 | M16: Target CSI tidak tercapai | N16: Realisasi Pencapaian Indeks Kepuasan Pelanggan sebesar 99,73% Tahun 2026 tidak tercapai | O16: a | P16: =CONCATENATE(E16,"-",L16,"-",O16) -> BID AGA-6-a | Q16: Keandalan pasokan listrik, sering terjadi Pemadaman. | R16: Indeks Kepuasan Pelanggan | S16: Skor | T16: >99,75% | U16: 0.9973 | V16: <99,73% | W16: Kontrol operasi - level operasi | X16: Evaluasi Realisasi Pencapaian TMP setiap Periodik dan melakukan Kompensasi bagi Pelanggan yang melewati TMP | Y16: 2. Cukup dan Efektif Sebagian | Z16: Kualitatif | AA16: Reputasi Perusahaan Menurun | AB16: Januari s.d Desember 2026 | AC16: Reputasi Perusahaan menurun akibat seringnya terjadi pemadaman | AD16: =IF(Z16="KUANTITATIF","Wajib Isi","Tidak Wajib") -> Tidak Wajib | AF16: 3 | AG16: ='Justifikasi Risk Assessment'!D152 -> 0.2 | AH16: 1 | AI16: =IF(Z16="kuantitatif",(AE16*AG16),(AF16*AH16*1%*$AI$3)) -> 18300000000 | AJ16: =INDEX(Source!$E$33:$I$37,MATCH(AH16,Source!$D$33:$D$37,0),MATCH(AF16,Source!$E$38:$I$38,0)) -> 10 | AK16: =LOOKUP(MATCH(AJ16,'Perhitungan Heatmap'!$D$9:$AB$9),'Perhitungan Heatmap'!$D$9:$AB$9,'Perhitungan Heatmap'!$D$10:$AB$10) -> Low To Moderate | AS16: 3 | AT16: 3 | AU16: 3 | AV16: 3 | AW16: 0.2 | AX16: 0.2 | AY16: 0.2 | AZ16: 0.2 | BA16: 2 | BB16: 2 | BC16: 2 | BD16: 2 | BE16: =AI16 -> 18300000000 | BF16: =BE16 -> 18300000000 | BG16: =BF16 -> 18300000000 | BH16: =BG16 -> 18300000000 | BI16: =INDEX(Source!$E$33:$I$37,MATCH(BA16,Source!$D$33:$D$37,0),MATCH(AS16,Source!$E$38:$I$38,0)) -> 11 | BJ16: =INDEX(Source!$E$33:$I$37,MATCH(BB16,Source!$D$33:$D$37,0),MATCH(AT16,Source!$E$38:$I$38,0)) -> 11 | BK16: =INDEX(Source!$E$33:$I$37,MATCH(BC16,Source!$D$33:$D$37,0),MATCH(AU16,Source!$E$38:$I$38,0)) -> 11 | BL16: =INDEX(Source!$E$33:$I$37,MATCH(BD16,Source!$D$33:$D$37,0),MATCH(AV16,Source!$E$38:$I$38,0)) -> 11 | BM16: =LOOKUP(MATCH(BI16,'Perhitungan Heatmap'!$D$9:$AB$9),'Perhitungan Heatmap'!$D$9:$AB$9,'Perhitungan Heatmap'!$D$10:$AB$10) -> Low To Moderate | BN16: =LOOKUP(MATCH(BJ16,'Perhitungan Heatmap'!$D$9:$AB$9),'Perhitungan Heatmap'!$D$9:$AB$9,'Perhitungan Heatmap'!$D$10:$AB$10) -> Low To Moderate | BO16: =LOOKUP(MATCH(BK16,'Perhitungan Heatmap'!$D$9:$AB$9),'Perhitungan Heatmap'!$D$9:$AB$9,'Perhitungan Heatmap'!$D$10:$AB$10) -> Low To Moderate | BP16: =LOOKUP(MATCH(BL16,'Perhitungan Heatmap'!$D$9:$AB$9),'Perhitungan Heatmap'!$D$9:$AB$9,'Perhitungan Heatmap'!$D$10:$AB$10) -> Low To Moderate | CB16: Reduce/Mitigate | CC16: Peningkatan Efektivitas Pelaksanaan Control | CD16: 1. Melakukan sosialisasi hasil SKP Tahun 2025. 2. Menindaklanjuti dan mengevaluasi action plan dan tindaklanjut hasil Survei Kepuasan Pelanggan (SKP) 2024 pada aplikasi CheSKP 3. Memetakan responden SKP 2026 4. Pelaksanaan SKP 2026 5. Melakukan koordinasi dengan pihak Surveyor dan Area Pelayanan terkait dengan rencana pelaksanaan SKP 6. Melakukan Pendampingan dalam proses pelaksanaan SKP 7. Melakukan Evaluasi Pelaksanaan SKP 8. Pemberian apresiasi pelanggan tercepat bayar | CE16: Tindaklanjut Action Plan SKP dalam aplikasi CheSKP | CF16: 400000000 | CJ16: VP AGA | CK16: 1 | CL16: 1 | CM16: 1 | CN16: 1 | CO16: 1 | CP16: 1 | CQ16: 1 | CR16: 1 | CS16: 1 | CT16: 1 | CU16: 1 | CV16: 1
B17: 7 | C17: PT Perusahaan Listrik Negara (Persero) | D17: PLN BATAM | E17: BID AGA | H17: Implementasi Roadmap Perbaikan Penerapan Manajemen Risiko SH/AP | I17: 2. Inovasi bisnis model | J17: 3.6.12 Peristiwa Risiko terkait hukum, reputasi, dan kepatuhan | K17: 12. Risiko Industri Umum - Reputasi & Kepatuhan | L17: 7 | M17: Nilai roadmap perbaikan risiko BID AGA tidak memenuhi target | N17: Nilai roadmap perbaikan risiko BID AGA tidak memenuhi target yang ditetapkan oleh Manajemen | O17: a | P17: =CONCATENATE(E17,"-",L17,"-",O17) -> BID AGA-7-a | Q17: Rsiko Bidang AGA belum dikelola dengan baik seperti belum ada sharing session, belum ada monitoring dan belum ada keterlibatan pimpinan dalam pengelolaan risiko | R17: Skor penerapan road map MR | S17: Skor | T17: 1 | U17: 0.99 | V17: <99% | W17: Kontrol kepatuhan (compliance) - level operasi | X17: Pununjukan Risk Officer untuk membantu memonitor pelaksanaan perbaikan road map MR | Y17: 2. Cukup dan Efektif Sebagian | Z17: Kualitatif | AA17: Tidak tercapai nilai road map MR | AB17: Januari s.d Desember 2026 | AC17: Deviasi nilai road map perbaikan MR antara target dan realisasi | AD17: =IF(Z17="KUANTITATIF","Wajib Isi","Tidak Wajib") -> Tidak Wajib | AF17: 1 | AG17: ='Justifikasi Risk Assessment'!F165 -> 0 | AH17: 1 | AI17: =IF(Z17="kuantitatif",(AE17*AG17),(AF17*AH17*1%*$AI$3)) -> 6100000000 | AJ17: =INDEX(Source!$E$33:$I$37,MATCH(AH17,Source!$D$33:$D$37,0),MATCH(AF17,Source!$E$38:$I$38,0)) -> 1 | AK17: =LOOKUP(MATCH(AJ17,'Perhitungan Heatmap'!$D$9:$AB$9),'Perhitungan Heatmap'!$D$9:$AB$9,'Perhitungan Heatmap'!$D$10:$AB$10) -> Low | AS17: 1 | AT17: 1 | AU17: 1 | AV17: 1 | AW17: 0.2 | AX17: 0.2 | AY17: 0.2 | AZ17: 0.2 | BA17: 1 | BB17: 1 | BC17: 1 | BD17: 1 | BE17: =AI17 -> 6100000000 | BF17: =BE17 -> 6100000000 | BG17: =BF17 -> 6100000000 | BH17: =BG17 -> 6100000000 | BI17: =INDEX(Source!$E$33:$I$37,MATCH(BA17,Source!$D$33:$D$37,0),MATCH(AS17,Source!$E$38:$I$38,0)) -> 1 | BJ17: =INDEX(Source!$E$33:$I$37,MATCH(BB17,Source!$D$33:$D$37,0),MATCH(AT17,Source!$E$38:$I$38,0)) -> 1 | BK17: =INDEX(Source!$E$33:$I$37,MATCH(BC17,Source!$D$33:$D$37,0),MATCH(AU17,Source!$E$38:$I$38,0)) -> 1 | BL17: =INDEX(Source!$E$33:$I$37,MATCH(BD17,Source!$D$33:$D$37,0),MATCH(AV17,Source!$E$38:$I$38,0)) -> 1 | BM17: =LOOKUP(MATCH(BI17,'Perhitungan Heatmap'!$D$9:$AB$9),'Perhitungan Heatmap'!$D$9:$AB$9,'Perhitungan Heatmap'!$D$10:$AB$10) -> Low | BN17: =LOOKUP(MATCH(BJ17,'Perhitungan Heatmap'!$D$9:$AB$9),'Perhitungan Heatmap'!$D$9:$AB$9,'Perhitungan Heatmap'!$D$10:$AB$10) -> Low | BO17: =LOOKUP(MATCH(BK17,'Perhitungan Heatmap'!$D$9:$AB$9),'Perhitungan Heatmap'!$D$9:$AB$9,'Perhitungan Heatmap'!$D$10:$AB$10) -> Low | BP17: =LOOKUP(MATCH(BL17,'Perhitungan Heatmap'!$D$9:$AB$9),'Perhitungan Heatmap'!$D$9:$AB$9,'Perhitungan Heatmap'!$D$10:$AB$10) -> Low | CB17: Accept/Monitor | CC17: Peningkatan Efektivitas Pelaksanaan Control | CD17: Pelaporan MR dan monitoring roadmap MR setiap bulan. | CE17: Laporan MR | CJ17: VP AGA | CL17: 1 | CM17: 1 | CN17: 1 | CO17: 1 | CP17: 1 | CQ17: 1 | CR17: 1 | CS17: 1 | CT17: 1 | CU17: 1 | CV17: 1
B18: 8 | C18: PT Perusahaan Listrik Negara (Persero) | D18: PLN BATAM | E18: BID AGA | H18: Kajian Biaya Penyambungan dan Tingkat Mutu Pelayanan | I18: 2. Inovasi bisnis model | J18: 3.6.16 Peristiwa Risiko terkait operasional | K18: 16. Risiko Industri Umum - Operasional | L18: 8 | M18: Keterlambatan tersedianya kajian BP dan TMP | N18: Kajian perubahan Biaya Penyambungan dan Tingkat Mutu Pelayanan belum tersedia pada waktu yang ditetapkan. | O18: a | P18: =CONCATENATE(E18,"-",L18,"-",O18) -> BID AGA-8-a | Q18: Milestone kajian Biaya Penyambungan dan Tingkat Mutu Pelayanan belum disusun | R18: Kajian BP dan TMP | S18: Bulan | T18: Oktober | U18: November | V18: Desember | W18: Kontrol operasi - level operasi | X18: Prosedur Evaluasi dan Pelapporan TMP | Y18: 2. Cukup dan Efektif Sebagian | Z18: Kualitatif | AA18: Tidak ada kajian / evaluasi BP dan TMP untuk menilai kelayakan BP dan TMPyang berjalan saat ini | AB18: Januari s.d Desember 2026 | AC18: Reputasi Perusahaan menurun akibat tidak adanya peningkatan Tingkat Mutu Pelayanan yang dirasakan pelanggan | AD18: =IF(Z18="KUANTITATIF","Wajib Isi","Tidak Wajib") -> Tidak Wajib | AF18: 1 | AG18: ='Justifikasi Risk Assessment'!D171 -> 20%% | AH18: 1 | AI18: =IF(Z18="kuantitatif",(AE18*AG18),(AF18*AH18*1%*$AI$3)) -> 6100000000 | AJ18: =INDEX(Source!$E$33:$I$37,MATCH(AH18,Source!$D$33:$D$37,0),MATCH(AF18,Source!$E$38:$I$38,0)) -> 1 | AK18: =LOOKUP(MATCH(AJ18,'Perhitungan Heatmap'!$D$9:$AB$9),'Perhitungan Heatmap'!$D$9:$AB$9,'Perhitungan Heatmap'!$D$10:$AB$10) -> Low | AS18: 3 | AT18: 3 | AU18: 3 | AV18: 3 | AW18: =AG18 -> 20%% | AX18: =AW18 -> 20%% | AY18: =AX18 -> 20%% | AZ18: =AY18 -> 20%% | BA18: 1 | BB18: 1 | BC18: 1 | BD18: 1 | BE18: =AI18 -> 6100000000 | BF18: =BE18 -> 6100000000 | BG18: =BF18 -> 6100000000 | BH18: =BG18 -> 6100000000 | BI18: =INDEX(Source!$E$33:$I$37,MATCH(BA18,Source!$D$33:$D$37,0),MATCH(AS18,Source!$E$38:$I$38,0)) -> 10 | BJ18: =INDEX(Source!$E$33:$I$37,MATCH(BB18,Source!$D$33:$D$37,0),MATCH(AT18,Source!$E$38:$I$38,0)) -> 10 | BK18: =INDEX(Source!$E$33:$I$37,MATCH(BC18,Source!$D$33:$D$37,0),MATCH(AU18,Source!$E$38:$I$38,0)) -> 10 | BL18: =INDEX(Source!$E$33:$I$37,MATCH(BD18,Source!$D$33:$D$37,0),MATCH(AV18,Source!$E$38:$I$38,0)) -> 10 | BM18: =LOOKUP(MATCH(BI18,'Perhitungan Heatmap'!$D$9:$AB$9),'Perhitungan Heatmap'!$D$9:$AB$9,'Perhitungan Heatmap'!$D$10:$AB$10) -> Low To Moderate | BN18: =LOOKUP(MATCH(BJ18,'Perhitungan Heatmap'!$D$9:$AB$9),'Perhitungan Heatmap'!$D$9:$AB$9,'Perhitungan Heatmap'!$D$10:$AB$10) -> Low To Moderate | BO18: =LOOKUP(MATCH(BK18,'Perhitungan Heatmap'!$D$9:$AB$9),'Perhitungan Heatmap'!$D$9:$AB$9,'Perhitungan Heatmap'!$D$10:$AB$10) -> Low To Moderate | BP18: =LOOKUP(MATCH(BL18,'Perhitungan Heatmap'!$D$9:$AB$9),'Perhitungan Heatmap'!$D$9:$AB$9,'Perhitungan Heatmap'!$D$10:$AB$10) -> Low To Moderate | CB18: Reduce/Mitigate | CC18: Peningkatan Efektivitas Pelaksanaan Control | CD18: 1. Menyusun dokumen pengadaan pada TW 2 2026 2. Koordinasi dengan konsultan eksternal | CE18: Dokumen Perjanjian Kerjasama dengan Konsultan | CF18: 2500000000 | CG18: Anggaran Operasi | CI18: Pengadaan | CJ18: VP AGA | CK18: 1 | CL18: 1 | CM18: 1 | CN18: 1 | CO18: 1 | CP18: 1 | CQ18: 1 | CR18: 1 | CS18: 1 | CT18: 1 | CU18: 1 | CV18: 1
B19: 9 | C19: PT Perusahaan Listrik Negara (Persero) | D19: PLN BATAM | E19: BID AGA | H19: Pengembangan Produk Layanan Niaga | I19: 3. Kepemimpinan teknologi | J19: 3.6.16 Peristiwa Risiko terkait operasional | K19: 16. Risiko Industri Umum - Operasional | L19: 9 | M19: Keterlambatan pengesahan produk layanan niaga yang baru | N19: Produk layanan niaga yang direncanakan 8 produk pada tahun 2026 terlambat disahkan Pejabat berwenang | O19: a | P19: =CONCATENATE(E19,"-",L19,"-",O19) -> BID AGA-9-a | Q19: Dokumen kajian produk layanan niaga terlambat disusun dan tidak dimonitor secara intensive | R19: Produk Layanan Niaga | S19: Produk | T19: >6 | U19: 6 | V19: <6 | W19: Kontrol operasi - level entitas/kantor pusat | X19: Prosedur Kebijakan dan Strategi Pemasaran | Y19: 2. Cukup dan Efektif Sebagian | Z19: Kuantitatif | AA19: Potensi kehilangan pendapatan bagi perusahaan | AB19: Desember 2026 | AC19: Delta Revenue dari produk layanan niaga | AD19: =IF(Z19="KUANTITATIF","Wajib Isi","Tidak Wajib") -> Wajib Isi | AE19: ='Justifikasi Risk Assessment'!D189 -> 1.0100404e+11 | AF19: 1 | AG19: ='Justifikasi Risk Assessment'!D191 -> 0 | AH19: 1 | AI19: =IF(Z19="kuantitatif",(AE19*AG19),(AF19*AH19*1%*$AI$3)) -> 0 | AJ19: =INDEX(Source!$E$33:$I$37,MATCH(AH19,Source!$D$33:$D$37,0),MATCH(AF19,Source!$E$38:$I$38,0)) -> 1 | AK19: =LOOKUP(MATCH(AJ19,'Perhitungan Heatmap'!$D$9:$AB$9),'Perhitungan Heatmap'!$D$9:$AB$9,'Perhitungan Heatmap'!$D$10:$AB$10) -> Low | AR19: ='Justifikasi Risk Assessment'!D189 -> 1.0100404e+11 | AS19: 1 | AT19: 1 | AU19: 1 | AV19: 1 | AW19: =AG19 -> 0 | AX19: =AW19 -> 0 | AY19: =AG19 -> 0 | AZ19: =AY19 -> 0 | BA19: 1 | BB19: 1 | BC19: 1 | BD19: 1 | BE19: =AO19*AW19 -> 0 | BF19: =AP19*AX19 -> 0 | BG19: =AQ19*AY19 -> 0 | BH19: =AR19*AZ19 -> 0 | BI19: =INDEX(Source!$E$33:$I$37,MATCH(BA19,Source!$D$33:$D$37,0),MATCH(AS19,Source!$E$38:$I$38,0)) -> 1 | BJ19: =INDEX(Source!$E$33:$I$37,MATCH(BB19,Source!$D$33:$D$37,0),MATCH(AT19,Source!$E$38:$I$38,0)) -> 1 | BK19: =INDEX(Source!$E$33:$I$37,MATCH(BC19,Source!$D$33:$D$37,0),MATCH(AU19,Source!$E$38:$I$38,0)) -> 1 | BL19: =INDEX(Source!$E$33:$I$37,MATCH(BD19,Source!$D$33:$D$37,0),MATCH(AV19,Source!$E$38:$I$38,0)) -> 1 | BM19: =LOOKUP(MATCH(BI19,'Perhitungan Heatmap'!$D$9:$AB$9),'Perhitungan Heatmap'!$D$9:$AB$9,'Perhitungan Heatmap'!$D$10:$AB$10) -> Low | BN19: =LOOKUP(MATCH(BJ19,'Perhitungan Heatmap'!$D$9:$AB$9),'Perhitungan Heatmap'!$D$9:$AB$9,'Perhitungan Heatmap'!$D$10:$AB$10) -> Low | BO19: =LOOKUP(MATCH(BK19,'Perhitungan Heatmap'!$D$9:$AB$9),'Perhitungan Heatmap'!$D$9:$AB$9,'Perhitungan Heatmap'!$D$10:$AB$10) -> Low | BP19: =LOOKUP(MATCH(BL19,'Perhitungan Heatmap'!$D$9:$AB$9),'Perhitungan Heatmap'!$D$9:$AB$9,'Perhitungan Heatmap'!$D$10:$AB$10) -> Low | CB19: Accept/Monitor | CC19: Peningkatan Efektivitas Pelaksanaan Control | CD19: 1. Menyusun Dokumen Manajemen Risiko (KKO, KKF, AR) 2. Menyusun draft Kebijakan Strategi Penjualan Peningkatan dan Pengendalian Penjualan Tenaga Listrik 3. Melakukan pembahasan secara intens dengan UB DISYAN, UB INFRA, BID MRK 4. Melakukan Strategi Pemasaran dengan paid media | CE19: 1. KKO, KKF, KR 2. Draft produk layanan niaga 3. Marketing tool program | CF19: 5883771685 | CJ19: VP AGA | CK19: 1 | CL19: 1 | CM19: 1 | CN19: 1 | CO19: 1 | CP19: 1 | CQ19: 1 | CR19: 1 | CS19: 1 | CT19: 1 | CU19: 1 | CV19: 1
